Workbook

Sheet 设备
A1: 入库时间 | B1: 设备类型 | C1: 设备型号 | D1: 设备SN | E1: SSID | F1: ICCID1 | G1: ICCID2 | H1: 去向 | I1: 出库时间 | J1: 出库历史 | K1: 设备状态 | L1: 卡1状态 | M1: 卡2状态
A2: 20250929 | B2: 4G-多模 | C2: MA425W-716 | D2: 253900001 | E2: WIFI-1390 | F2: 8986112522008536444 | G2: 8986112522008536429 | H2: 苏昶 | I2: 2025年11月3日 | L2: 销户 | M2: 销户
A3: 20250929 | B3: 4G-多模 | C3: MA425W-716 | D3: 253900002 | E3: WIFI-1392 | F3: 8986032444201760289 | G3: 89860812192440028305 | L3: =_xlfn.XLOOKUP(F3,物联网卡!B:B,物联网卡!F:F,"") -> 未激活 | M3: =_xlfn.XLOOKUP(G3,物联网卡!B:B,物联网卡!F:F,"") -> 未激活
A4: 20250929 | B4: 4G-多模 | C4: MA425W-716 | H4: 秦总带走 | L4: 销户 | M4: 销户
A5: 20250929 | B5: 4G-多模 | C5: MA425W-716 | D5: 253900003 | E5: WIFI-1394 | F5: 8986032444201760307 | G5: 89860812192440028322 | H5: 帝恩斯 | I5: 2026年3月31日 | J5: 一见小哥 | L5: =_xlfn.XLOOKUP(F5,物联网卡!B:B,物联网卡!F:F,"") -> 未激活 | M5: =_xlfn.XLOOKUP(G5,物联网卡!B:B,物联网卡!F:F,"") -> 激活
A6: 20250929 | B6: 4G-多模 | C6: MA425W-716 | D6: 253900004 | E6: WIFI-1396 | F6: 8986112522008536577 | G6: 8986112522008536426 | H6: 苏昶 | I6: 2025年11月3日 | L6: 销户 | M6: 销户
A7: 20250929 | B7: 4G-多模 | C7: MA425W-716 | D7: 253900005 | E7: WIFI-1398 | F7: 8986112522008536578 | G7: 8986112522008536427 | H7: 林云带走 | L7: 销户 | M7: 销户
A8: 20250929 | B8: 4G-多模 | C8: MA425W-716 | D8: 253900006 | E8: WIFI-139A | F8: 8986032444201760290 | G8: 89860812192440028306 | L8: =_xlfn.XLOOKUP(F8,物联网卡!B:B,物联网卡!F:F,"") -> 未激活 | M8: =_xlfn.XLOOKUP(G8,物联网卡!B:B,物联网卡!F:F,"") -> 未激活
A9: 20250929 | B9: 4G-多模 | C9: MA425W-716 | D9: 253900007 | E9: WIFI-139C | F9: 8986112522008536579 | G9: 8986112522008536428 | H9: 苏昶 | I9: 2025年11月3日 | L9: 销户 | M9: 销户
A10: 20250929 | B10: 4G-多模 | C10: MA425W-716 | D10: 253900008 | E10: WIFI-139E | F10: 8986032444201760297 | G10: 89860812192440028312 | J10: 帝恩斯 | K10: 短路损坏 | L10: =_xlfn.XLOOKUP(F10,物联网卡!B:B,物联网卡!F:F,"") -> 未激活 | M10: =_xlfn.XLOOKUP(G10,物联网卡!B:B,物联网卡!F:F,"") -> 激活
A11: 20250929 | B11: 4G-多模 | C11: MA425W-716 | D11: 253900009 | E11: WIFI-13A0 | F11: 8986032444201760291 | G11: 89860812192440028307 | L11: =_xlfn.XLOOKUP(F11,物联网卡!B:B,物联网卡!F:F,"") -> 未激活 | M11: =_xlfn.XLOOKUP(G11,物联网卡!B:B,物联网卡!F:F,"") -> 未激活
A12: 20250929 | B12: 4G-多模 | C12: MA425W-716 | D12: 253900010 | E12: WIFI-13A2 | F12: 8986032444201760293 | G12: 89860812192440028309 | L12: =_xlfn.XLOOKUP(F12,物联网卡!B:B,物联网卡!F:F,"") -> 未激活 | M12: =_xlfn.XLOOKUP(G12,物联网卡!B:B,物联网卡!F:F,"") -> 未激活
A13: 20250929 | B13: 4G-多模 | C13: MA425W-716 | D13: 253900011 | E13: WIFI-13A4 | F13: 8986032444201760296 | G13: 89860812192440028311 | L13: =_xlfn.XLOOKUP(F13,物联网卡!B:B,物联网卡!F:F,"") -> 激活 | M13: =_xlfn.XLOOKUP(G13,物联网卡!B:B,物联网卡!F:F,"") -> 激活
A14: 20250929 | B14: 4G-多模 | C14: MA425W-716 | D14: 253900012 | E14: WIFI-13A6 | F14: 8986032444201760306 | G14: 89860812192440028321 | J14: 帝恩斯,一见小哥 | L14: =_xlfn.XLOOKUP(F14,物联网卡!B:B,物联网卡!F:F,"") -> 未激活 | M14: =_xlfn.XLOOKUP(G14,物联网卡!B:B,物联网卡!F:F,"") -> 激活
A15: 20250929 | B15: 4G-多模 | C15: MA425W-716 | D15: 253900014 | E15: WIFI-13A8 | F15: 8986032444201760298 | G15: 89860812192440028313 | L15: =_xlfn.XLOOKUP(F15,物联网卡!B:B,物联网卡!F:F,"") -> 停用 | M15: =_xlfn.XLOOKUP(G15,物联网卡!B:B,物联网卡!F:F,"") -> 停用
A16: 20250929 | B16: 4G-多模 | C16: MA425W-716 | D16: 253900015 | E16: WIFI-13AA | F16: 8986032444201760295 | G16: 89860812192440028324 | L16: =_xlfn.XLOOKUP(F16,物联网卡!B:B,物联网卡!F:F,"") -> 未激活 | M16: =_xlfn.XLOOKUP(G16,物联网卡!B:B,物联网卡!F:F,"") -> 未激活
A17: 20250929 | B17: 4G-多模 | C17: MA425W-716 | D17: 253900017 | E17: WIFI-13AE | F17: 8986032444201760299 | G17: 89860812192440028314 | H17: 沙县 - 瑞景店 | I17: 46120 | L17: =_xlfn.XLOOKUP(F17,物联网卡!B:B,物联网卡!F:F,"") -> 激活 | M17: =_xlfn.XLOOKUP(G17,物联网卡!B:B,物联网卡!F:F,"") -> 激活
A18: 20250929 | B18: 4G-多模 | C18: MA425W-716 | D18: 253900017 | E18: WIFI-13B0 | F18: 8986112522008536571 | G18: 8986112522008536589 | H18: 苏昶 | I18: 2025年11月3日 | L18: 销户 | M18: 销户
A19: 20250929 | B19: 4G-多模 | C19: MA425W-716 | D19: 253900018 | E19: WIFI-13B2 | F19: 8986032444201760294 | G19: 89860812192440028310 | L19: =_xlfn.XLOOKUP(F19,物联网卡!B:B,物联网卡!F:F,"") -> 未激活 | M19: =_xlfn.XLOOKUP(G19,物联网卡!B:B,物联网卡!F:F,"") -> 未激活
A20: 20250929 | B20: 4G-多模 | C20: MA425W-716 | D20: 253900019 | E20: WIFI-13B4 | F20: 8986032444201760292 | G20: 89860812192440028308 | L20: =_xlfn.XLOOKUP(F20,物联网卡!B:B,物联网卡!F:F,"") -> 未激活 | M20: =_xlfn.XLOOKUP(G20,物联网卡!B:B,物联网卡!F:F,"") -> 未激活
A21: 20250929 | B21: 4G-多模 | C21: MA425W-716 | D21: 253900020 | E21: WIFI-13B6 | F21: 8986032444201760308 | G21: 89860812192440028323 | H21: 帝恩斯 | I21: 2026年3月31日 | J21: 游总 | L21: =_xlfn.XLOOKUP(F21,物联网卡!B:B,物联网卡!F:F,"") -> 未激活 | M21: =_xlfn.XLOOKUP(G21,物联网卡!B:B,物联网卡!F:F,"") -> 激活
A22: 20251223 | B22: 4G-多模 | C22: MA425W-716 | D22: 202512270100 | E22: WIFI-0010 | F22: 89860324442017602438 | G22: 89860812192440028350 | L22: =_xlfn.XLOOKUP(F22,物联网卡!B:B,物联网卡!F:F,"") -> 未激活 | M22: =_xlfn.XLOOKUP(G22,物联网卡!B:B,物联网卡!F:F,"") -> 未激活
A23: 20251223 | B23: 4G-多模 | C23: MA425W-716 | D23: 202512270101 | E23: WIFI-0012 | F23: 89860324442017602404 | G23: 89860812192440028374 | L23: =_xlfn.XLOOKUP(F23,物联网卡!B:B,物联网卡!F:F,"") -> 未激活 | M23: =_xlfn.XLOOKUP(G23,物联网卡!B:B,物联网卡!F:F,"") -> 未激活
A24: 20251223 | B24: 4G-多模 | C24: MA425W-716 | D24: 202512270102 | E24: WIFI-0014 | F24: 89860324442017602420 | G24: 89860812192440028373 | L24: =_xlfn.XLOOKUP(F24,物联网卡!B:B,物联网卡!F:F,"") -> 未激活 | M24: =_xlfn.XLOOKUP(G24,物联网卡!B:B,物联网卡!F:F,"") -> 未激活
A25: 20251223 | B25: 4G-多模 | C25: MA425W-716 | D25: 202512270103 | E25: WIFI-0016 | F25: 89860324442017602479 | G25: 89860812192440028372 | L25: =_xlfn.XLOOKUP(F25,物联网卡!B:B,物联网卡!F:F,"") -> 未激活 | M25: =_xlfn.XLOOKUP(G25,物联网卡!B:B,物联网卡!F:F,"") -> 未激活
A26: 20251223 | B26: 4G-多模 | C26: MA425W-716 | D26: 202512270104 | E26: WIFI-0018 | F26: 89860324442017602412 | G26: 89860812192440028351 | H26: 沙县 - 蔡塘店 | I26: 46030 | L26: =_xlfn.XLOOKUP(F26,物联网卡!B:B,物联网卡!F:F,"") -> 停用 | M26: =_xlfn.XLOOKUP(G26,物联网卡!B:B,物联网卡!F:F,"") -> 停用
A27: 20251223 | B27: 4G-多模 | C27: MA425W-716 | D27: 202512270105 | E27: WIFI-001A | F27: 89860324442017602842 | G27: 89860812192440028371 | L27: =_xlfn.XLOOKUP(F27,物联网卡!B:B,物联网卡!F:F,"") -> 未激活 | M27: =_xlfn.XLOOKUP(G27,物联网卡!B:B,物联网卡!F:F,"") -> 未激活
A28: 20251223 | B28: 4G-多模 | C28: MA425W-716 | D28: 202512270106 | E28: WIFI-001C | F28: 89860324442017602859 | G28: 89860812192440028370 | L28: =_xlfn.XLOOKUP(F28,物联网卡!B:B,物联网卡!F:F,"") -> 未激活 | M28: =_xlfn.XLOOKUP(G28,物联网卡!B:B,物联网卡!F:F,"") -> 未激活
A29: 20251223 | B29: 4G-多模 | C29: MA425W-716 | D29: 202512270107 | E29: WIFI-001E | F29: 89860324442017602867 | G29: 89860812192440028369 | L29: =_xlfn.XLOOKUP(F29,物联网卡!B:B,物联网卡!F:F,"") -> 未激活 | M29: =_xlfn.XLOOKUP(G29,物联网卡!B:B,物联网卡!F:F,"") -> 未激活
A30: 20251223 | B30: 4G-多模 | C30: MA425W-716 | D30: 202512270108 | E30: WIFI-0020 | F30: 89860324442017602545 | G30: 89860812192440028368 | L30: =_xlfn.XLOOKUP(F30,物联网卡!B:B,物联网卡!F:F,"") -> 未激活 | M30: =_xlfn.XLOOKUP(G30,物联网卡!B:B,物联网卡!F:F,"") -> 未激活
A31: 20251223 | B31: 4G-多模 | C31: MA425W-716 | D31: 202512270109 | E31: WIFI-0022 | F31: 89860324442017602552 | G31: 89860812192440028352 | L31: =_xlfn.XLOOKUP(F31,物联网卡!B:B,物联网卡!F:F,"") -> 未激活 | M31: =_xlfn.XLOOKUP(G31,物联网卡!B:B,物联网卡!F:F,"") -> 未激活
A32: 20251223 | B32: 4G-多模 | C32: MA425W-716 | D32: 202512270110 | E32: WIFI-0024 | F32: 89860324442017602560 | G32: 89860812192440028353 | L32: =_xlfn.XLOOKUP(F32,物联网卡!B:B,物联网卡!F:F,"") -> 未激活 | M32: =_xlfn.XLOOKUP(G32,物联网卡!B:B,物联网卡!F:F,"") -> 未激活
A33: 20251223 | B33: 4G-多模 | C33: MA425W-716 | D33: 202512270111 | E33: WIFI-0026 | F33: 89860324442017602578 | G33: 89860812192440028354 | L33: =_xlfn.XLOOKUP(F33,物联网卡!B:B,物联网卡!F:F,"") -> 未激活 | M33: =_xlfn.XLOOKUP(G33,物联网卡!B:B,物联网卡!F:F,"") -> 未激活
A34: 20251223 | B34: 4G-多模 | C34: MA425W-716 | D34: 202512270112 | E34: WIFI-0028 | F34: 89860324442017602586 | G34: 89860812192440028355 | L34: =_xlfn.XLOOKUP(F34,物联网卡!B:B,物联网卡!F:F,"") -> 未激活 | M34: =_xlfn.XLOOKUP(G34,物联网卡!B:B,物联网卡!F:F,"") -> 未激活
A35: 20251223 | B35: 4G-多模 | C35: MA425W-716 | D35: 202512270113 | E35: WIFI-002A | F35: 89860324442017602487 | G35: 89860812192440028366 | L35: =_xlfn.XLOOKUP(F35,物联网卡!B:B,物联网卡!F:F,"") -> 未激活 | M35: =_xlfn.XLOOKUP(G35,物联网卡!B:B,物联网卡!F:F,"") -> 未激活
A36: 20251223 | B36: 4G-多模 | C36: MA425W-716 | D36: 202512270114 | E36: WIFI-002E | F36: 89860324442017602594 | G36: 89860812192440028367 | L36: =_xlfn.XLOOKUP(F36,物联网卡!B:B,物联网卡!F:F,"") -> 未激活 | M36: =_xlfn.XLOOKUP(G36,物联网卡!B:B,物联网卡!F:F,"") -> 未激活
A37: 20251223 | B37: 4G-多模 | C37: MA425W-716 | D37: 202512270115 | E37: WIFI-0030 | F37: 89860324442017602610 | G37: 89860812192440028364 | L37: =_xlfn.XLOOKUP(F37,物联网卡!B:B,物联网卡!F:F,"") -> 未激活 | M37: =_xlfn.XLOOKUP(G37,物联网卡!B:B,物联网卡!F:F,"") -> 未激活
A38: 20251223 | B38: 4G-多模 | C38: MA425W-716 | D38: 202512270116 | E38: WIFI-0032 | F38: 89860324442017602602 | G38: 89860812192440028365 | H38: 游政贤 | L38: =_xlfn.XLOOKUP(F38,物联网卡!B:B,物联网卡!F:F,"") -> 未激活 | M38: =_xlfn.XLOOKUP(G38,物联网卡!B:B,物联网卡!F:F,"") -> 停用
A39: 20251223 | B39: 4G-多模 | C39: MA425W-716 | D39: 202512270117 | E39: WIFI-0034 | F39: 89860324442017602628 | G39: 89860812192440028363 | L39: =_xlfn.XLOOKUP(F39,物联网卡!B:B,物联网卡!F:F,"") -> 未激活 | M39: =_xlfn.XLOOKUP(G39,物联网卡!B:B,物联网卡!F:F,"") -> 未激活
A40: 20251223 | B40: 4G-多模 | C40: MA425W-716 | D40: 202512270118 | E40: WIFI-0036 | F40: 89860324442017602636 | G40: 89860812192440028357 | H40: 沙县 - 钟宅店 | I40: 2026年6月15日 | L40: =_xlfn.XLOOKUP(F40,物联网卡!B:B,物联网卡!F:F,"") -> 未激活 | M40: =_xlfn.XLOOKUP(G40,物联网卡!B:B,物联网卡!F:F,"") -> 未激活
...

Sheet 物联网卡
A1: 入库时间 | B1: iccid | C1: 运营商 | D1: 通讯类型 | E1: 设备sn | F1: 卡状态
A2: 2025.12.9 | B2: 89860324442017602438 | C2: 电信 | D2: 4G | E2: 202512270100 | F2: 未激活
A3: 2025.12.9 | B3: 89860324442017602404 | C3: 电信 | D3: 4G | E3: 202512270101 | F3: 未激活
A4: 2025.12.9 | B4: 89860324442017602420 | C4: 电信 | D4: 4G | E4: 202512270102 | F4: 未激活
A5: 2025.12.9 | B5: 89860324442017602479 | C5: 电信 | D5: 4G | E5: 202512270103 | F5: 未激活
A6: 2025.12.9 | B6: 89860324442017602412 | C6: 电信 | D6: 4G | E6: 202512270104 | F6: 停用
A7: 2025.12.9 | B7: 89860324442017602842 | C7: 电信 | D7: 4G | E7: 202512270105 | F7: 未激活
A8: 2025.12.9 | B8: 89860324442017602859 | C8: 电信 | D8: 4G | E8: 202512270106 | F8: 未激活
A9: 2025.12.9 | B9: 89860324442017602867 | C9: 电信 | D9: 4G | E9: 202512270107 | F9: 未激活
A10: 2025.12.9 | B10: 89860324442017602545 | C10: 电信 | D10: 4G | E10: 202512270108 | F10: 未激活
A11: 2025.12.9 | B11: 89860324442017602552 | C11: 电信 | D11: 4G | E11: 202512270109 | F11: 未激活
A12: 2025.12.9 | B12: 89860324442017602560 | C12: 电信 | D12: 4G | E12: 202512270110 | F12: 未激活
... A101: 2025.12.9 | B101: 89860812192440028332 | C101: 移动 | D101: 4G | E101: 202512270150 | F101: 未激活
A102: 2025.12.9 | B102: 8986032444201760308 | C102: 电信 | D102: 4G | E102: 253900020 | F102: 未激活
A103: 2025.12.9 | B103: 8986032444201760307 | C103: 电信 | D103: 4G | E103: 253900003 | F103: 未激活
A104: 2025.12.9 | B104: 8986032444201760306 | C104: 电信 | D104: 4G | E104: 253900012 | F104: 未激活
A105: 2025.12.9 | B105: 8986032444201760305 | C105: 电信 | D105: 4G | F105: 未激活
A106: 2025.12.9 | B106: 8986032444201760304 | C106: 电信 | D106: 4G | F106: 未激活
A107: 2025.12.9 | B107: 8986032444201760303 | C107: 电信 | D107: 4G | F107: 未激活
A108: 2025.12.9 | B108: 8986032444201760302 | C108: 电信 | D108: 4G | F108: 未激活
A109: 2025.12.9 | B109: 8986032444201760301 | C109: 电信 | D109: 4G | F109: 未激活
A110: 2025.12.9 | B110: 8986032444201760300 | C110: 电信 | D110: 4G | F110: 未激活
A111: 2025.12.9 | B111: 8986032444201760299 | C111: 电信 | D111: 4G | E111: 253900017 | F111: 激活
A112: 2025.12.9 | B112: 8986032444201760298 | C112: 电信 | D112: 4G | E112: 253900014 | F112: 停用
A113: 2025.12.9 | B113: 8986032444201760297 | C113: 电信 | D113: 4G | E113: 253900008 | F113: 未激活
A114: 2025.12.9 | B114: 8986032444201760296 | C114: 电信 | D114: 4G | E114: 253900011 | F114: 激活
A115: 2025.12.9 | B115: 8986032444201760295 | C115: 电信 | D115: 4G | E115: 253900015 | F115: 未激活
A116: 2025.12.9 | B116: 8986032444201760294 | C116: 电信 | D116: 4G | E116: 253900018 | F116: 未激活
A117: 2025.12.9 | B117: 8986032444201760293 | C117: 电信 | D117: 4G | E117: 253900010 | F117: 未激活
A118: 2025.12.9 | B118: 8986032444201760292 | C118: 电信 | D118: 4G | E118: 253900019 | F118: 未激活
A119: 2025.12.9 | B119: 8986032444201760291 | C119: 电信 | D119: 4G | E119: 253900009 | F119: 未激活
A120: 2025.12.9 | B120: 8986032444201760290 | C120: 电信 | D120: 4G | E120: 253900006 | F120: 未激活
A121: 2025.12.9 | B121: 8986032444201760289 | C121: 电信 | D121: 4G | E121: 253900002 | F121: 未激活
A122: 2025.12.9 | B122: 89860812192440028324 | C122: 移动 | D122: 4G | E122: 253900015 | F122: 未激活
... A125: 2025.12.9 | B125: 89860812192440028321 | C125: 移动 | D125: 4G | E125: 253900012 | F125: 激活
A126: 2025.12.9 | B126: 89860812192440028320 | C126: 移动 | D126: 4G | F126: 未激活
A127: 2025.12.9 | B127: 89860812192440028319 | C127: 移动 | D127: 4G | F127: 未激活
A128: 2025.12.9 | B128: 89860812192440028318 | C128: 移动 | D128: 4G | F128: 未激活
A129: 2025.12.9 | B129: 89860812192440028317 | C129: 移动 | D129: 4G | F129: 未激活
A130: 2025.12.9 | B130: 89860812192440028316 | C130: 移动 | D130: 4G | F130: 未激活
...

Sheet 边缘盒子
A1: 入库时间 | B1: 出库时间 | C1: SN | D1: 归属客户 | E1: 归属门店 | F1: 门店地址 | G1: 所在城市 | H1: 设备状态
A2: 20260507 | B2: 20260525 | C2: b4f508160001 | D2: 247FITNESS | E2: 宝龙 | F2: 厦门市湖里区宝龙一城 | G2: 厦门 | H2: 启用
A3: 20260507 | B3: 20260519 | C3: b4f508160006 | D3: 247FITNESS | E3: 禹悦汇 | F3: 厦门市思明区厦禾路882-888号禹悦汇A区2F-132 | G3: 厦门 | H3: 启用
A4: 20260323 | B4: 20260416 | C4: ba10a3e7b8dc | D4: 247FITNESS | E4: 湖里公園 | F4: 厦门市湖里区华泰路260-103号 | G4: 厦门 | H4: 启用
A5: 20260323 | B5: 20260416 | C5: 3eeade2fa9dd | D5: 247FITNESS | E5: sm店 | F5: 厦门市湖里区嘉禾路468-3号602室 | G5: 厦门 | H5: 启用
A6: 20260323 | B6: 20260416 | C6: eae0bce3c398 | D6: 247FITNESS | E6: 五缘湾 | F6: 厦门市湖里区金湖路516号五缘湾天虹购物中心商场L3层54铺 | G6: 厦门 | H6: 启用
A7: 20260323 | B7: 20260424 | C7: 760823c706d5 | D7: 247FITNESS | E7: 普陀环球港店 | F7: 上海市普陀区中山北路3300号L4层L4137-4138商铺 | G7: 上海 | H7: 启用
A8: 20260323 | B8: 20260424 | C8: 760b67a8a8fc | D8: 247FITNESS | E8: 虹口月亮湾店 | F8: 上海市虹口区瑞虹路188号5层506A、506B室 | G8: 上海 | H8: 启用
A9: 20260323 | B9: 20260424 | C9: 7669bd37fadf | D9: 247FITNESS | E9: 长宁金虹桥店 | F9: 上海市长宁区茅台路179号3层1317/L318/L319/L320 | G9: 上海 | H9: 启用
A10: 20260323 | B10: 20260424 | C10: d675fb275ee4 | D10: 247FITNESS | E10: 黄浦巴黎春天 | F10: 上海市黄浦区淮海中路939-949号1号楼地上六层#1号商铺 | G10: 上海 | H10: 启用
A11: 20260323 | B11: 20260424 | C11: 5e55482bf747 | D11: 247FITNESS | E11: 静安中信泰富 | F11: 上海市静安区南京西路1168号三层308单元 | G11: 上海 | H11: 启用
A12: 20260507 | B12: 20260518 | C12: b4f508160005 | D12: 247FITNESS | E12: 观瑭2 | F12: 香港九龙观塘巧明街4-96号 | G12: 香港 | H12: 启用
A13: 20260323 | B13: 20260424 | C13: 4281dccab1d8 | D13: 自用 | E13: 网宇集团 | F13: 厦门市集美区软件园三期F10栋4F | G13: 厦门 | H13: 启用
A14: 20260507 | B14: 20260615 | C14: b4f508160002 | D14: 量时光 | E14: 万象城 | F14: 福建省厦门市思明区湖滨东路99号 | G14: 厦门 | H14: 启用
A15: 20260507 | B15: 20260615 | C15: b4f508160003 | D15: 量时光 | E15: 柚子番 | F15: 福建省厦门市思明区洪莲路20号 | G15: 厦门 | H15: 启用
A16: 20260507 | B16: 20260615 | C16: b4f508160007 | D16: 量时光 | E16: SM | F16: 厦门市湖里区嘉禾路468-3号602室 | G16: 厦门 | H16: 启用
A17: 20260507 | B17: 20260615 | C17: b4f508160010 | D17: 量时光 | E17: 禾祥西 | F17: 福建省厦门市思明区后江埭西路西侧, | G17: 厦门 | H17: 启用
A18: 20260323 | C18: 942aea44bbcde9d4 | H18: 未启用
A19: 20260507 | C19: b4f508160004 | H19: 未启用
A20: 20260507 | C20: b4f508160008 | H20: 未启用
A21: 20260507 | C21: b4f508160009 | D21: 加减健身 | H21: 未启用
